<?xml version="1.0" encoding="UTF-8"?>
<testsuite errors="1" failures="0" file="test_combine_enum.py" name="test_combine_enum.TestCombineEnum-20200831200112" skipped="0" tests="1" time="0.000" timestamp="2020-08-31T20:01:12">
	<testcase classname="test_combine_enum.TestCombineEnum" file="spec/construct/test_combine_enum.py" line="8" name="test_combine_enum" time="0.000" timestamp="2020-08-31T20:01:12">
		<error message="global name 'CombineEnum' is not defined" type="NameError">
<![CDATA[Traceback (most recent call last):
  File "/home/travis/build/kaitai-io/ci_targets/tests/spec/construct/test_combine_enum.py", line 11, in test_combine_enum
    self.assertEqual(r.enum_u4, CombineEnum.Animal.pig)
NameError: global name 'CombineEnum' is not defined
]]>		</error>
		<system-out>
<![CDATA[]]>		</system-out>
		<system-err>
<![CDATA[]]>		</system-err>
	</testcase>
</testsuite>
