<?xml version="1.0" encoding="UTF-8"?>
<testsuite errors="0" failures="1" file="test_process_coerce_usertype2.py" name="test_process_coerce_usertype2.TestProcessCoerceUsertype2-20220728001409" skipped="0" tests="1" time="0.001" timestamp="2022-07-28T00:14:09">
	<testcase classname="test_process_coerce_usertype2.TestProcessCoerceUsertype2" file="spec/construct/test_process_coerce_usertype2.py" line="8" name="test_process_coerce_usertype2" time="0.001" timestamp="2022-07-28T00:14:09">
		<failure message="3907578088 != 1111638594" type="AssertionError">
<![CDATA[Traceback (most recent call last):
  File "/home/travis/build/kaitai-io/ci_targets/tests/spec/construct/test_process_coerce_usertype2.py", line 13, in test_process_coerce_usertype2
    self.assertEqual(r.records[1].buf.value, 1111638594)
AssertionError: 3907578088 != 1111638594
]]>		</failure>
		<system-out>
<![CDATA[]]>		</system-out>
		<system-err>
<![CDATA[]]>		</system-err>
	</testcase>
</testsuite>
