<?xml version="1.0" encoding="UTF-8"?>
<testsuite errors="1" failures="0" file="test_enum_invalid.py" name="test_enum_invalid.TestEnumInvalid-20211115222314" skipped="0" tests="1" time="0.000" timestamp="2021-11-15T22:23:14">
	<testcase classname="test_enum_invalid.TestEnumInvalid" file="spec/construct/test_enum_invalid.py" line="8" name="test_enum_invalid" time="0.000" timestamp="2021-11-15T22:23:14">
		<error message="global name 'EnumInvalid' is not defined" type="NameError">
<![CDATA[Traceback (most recent call last):
  File "/home/travis/build/kaitai-io/ci_targets/tests/spec/construct/test_enum_invalid.py", line 11, in test_enum_invalid
    self.assertEqual(r.pet_1, EnumInvalid.Animal.dog)
NameError: global name 'EnumInvalid' is not defined
]]>		</error>
		<system-out>
<![CDATA[]]>		</system-out>
		<system-err>
<![CDATA[]]>		</system-err>
	</testcase>
</testsuite>
