<?xml version="1.0" encoding="UTF-8"?>
<testsuite name="test_combine_enum.TestCombineEnum-20211114130613" tests="1" file="test_combine_enum.py" time="0.001" timestamp="2021-11-14T13:06:13" failures="0" errors="1" skipped="0">
	<testcase classname="test_combine_enum.TestCombineEnum" name="test_combine_enum" time="0.001" timestamp="2021-11-14T13:06:13" file="spec/construct/test_combine_enum.py" line="8">
		<error type="NameError" message="name 'CombineEnum' is not defined"><![CDATA[Traceback (most recent call last):
  File "/home/travis/build/kaitai-io/ci_targets/tests/spec/construct/test_combine_enum.py", line 11, in test_combine_enum
    self.assertEqual(r.enum_u4, CombineEnum.Animal.pig)
NameError: name 'CombineEnum' is not defined
]]></error>
	</testcase>
</testsuite>
