<?xml version="1.0" encoding="UTF-8"?>
<testsuite name="test_repeat_until_complex.TestRepeatUntilComplex-20201106111735" tests="1" file="test_repeat_until_complex.py" time="0.002" timestamp="2020-11-06T11:17:35" failures="1" errors="0" skipped="0">
	<testcase classname="test_repeat_until_complex.TestRepeatUntilComplex" name="test_repeat_until_complex" time="0.002" timestamp="2020-11-06T11:17:35" file="spec/construct/test_repeat_until_complex.py" line="8">
		<failure type="AssertionError" message="&lt;bound method Container.values of Contain[43 chars]4]))&gt; != [1, 2, 3, 4]"><![CDATA[Traceback (most recent call last):
  File "/home/travis/build/kaitai-io/ci_targets/tests/spec/construct/test_repeat_until_complex.py", line 12, in test_repeat_until_complex
    self.assertEqual(r.first[0].values, [(0 + 1), 2, 3, 4])
AssertionError: <bound method Container.values of Contain[43 chars]4]))> != [1, 2, 3, 4]
]]></failure>
	</testcase>
</testsuite>
