<?xml version="1.0" encoding="UTF-8"?>
<testsuite errors="1" failures="0" file="test_process_repeat_usertype.py" name="test_process_repeat_usertype.TestProcessRepeatUsertype-20200214235548" skipped="0" tests="1" time="0.001" timestamp="2020-02-14T23:55:48">
	<testcase classname="test_process_repeat_usertype.TestProcessRepeatUsertype" file="spec/python/test_process_repeat_usertype.py" line="8" name="test_process_repeat_usertype" time="0.001" timestamp="2020-02-14T23:55:48">
		<error message="'ProcessRepeatUsertype' object has no attribute '_raw__raw_blocks'" type="AttributeError">
<![CDATA[Traceback (most recent call last):
  File "/home/travis/build/kaitai-io/ci_targets/tests/spec/python/test_process_repeat_usertype.py", line 9, in test_process_repeat_usertype
    with ProcessRepeatUsertype.from_file('src/process_xor_4.bin') as r:
  File "/home/travis/build/kaitai-io/ci_targets/runtime/python/kaitaistruct.py", line 35, in from_file
    return cls(KaitaiStream(f))
  File "/home/travis/build/kaitai-io/ci_targets/tests/compiled/python/process_repeat_usertype.py", line 16, in __init__
    self._read()
  File "/home/travis/build/kaitai-io/ci_targets/tests/compiled/python/process_repeat_usertype.py", line 22, in _read
    self._raw__raw_blocks[i] = self._io.read_bytes(5)
AttributeError: 'ProcessRepeatUsertype' object has no attribute '_raw__raw_blocks'
]]>		</error>
		<system-out>
<![CDATA[]]>		</system-out>
		<system-err>
<![CDATA[]]>		</system-err>
	</testcase>
</testsuite>
