<?xml version="1.0" encoding="UTF-8"?>
<testsuite errors="1" failures="0" name="test_position_to_end.TestPositionToEnd-20180205014306" skipped="0" tests="1" time="0.000">
	<testcase classname="test_position_to_end.TestPositionToEnd" name="test_position_to_end" time="0.000">
		<error message="I/O operation on closed file" type="ValueError">
<![CDATA[Traceback (most recent call last):
  File "/home/travis/build/kaitai-io/ci_targets/tests/spec/python/test_position_to_end.py", line 9, in test_position_to_end
    self.assertEqual(r.index.foo, 0x42)
  File "/home/travis/build/kaitai-io/ci_targets/tests/compiled/python/position_to_end.py", line 37, in index
    _pos = self._io.pos()
  File "/home/travis/build/kaitai-io/ci_targets/runtime/python/kaitaistruct.py", line 76, in pos
    return self._io.tell()
ValueError: I/O operation on closed file
]]>		</error>
	</testcase>
	<system-out>
<![CDATA[]]>	</system-out>
	<system-err>
<![CDATA[]]>	</system-err>
</testsuite>
