<?xml version="1.0" encoding="UTF-8"?>
<testsuite errors="15" failures="0" file="unittest/loader.py" name="unittest.loader.ModuleImportFailure-20210206143509" skipped="0" tests="15" time="0.003" timestamp="2021-02-06T14:35:09">
	<testcase classname="unittest.loader.ModuleImportFailure" file="/opt/python/2.7.14/lib/python2.7/unittest/loader.py" line="31" name="test_expr_2" time="0.000" timestamp="2021-02-06T14:35:09">
		<error message="Failed to import test module: test_expr_2
Traceback (most recent call last):
  File &quot;/opt/python/2.7.14/lib/python2.7/unittest/loader.py&quot;, line 254, in _find_tests
    module = self._get_module_from_name(name)
  File &quot;/opt/python/2.7.14/lib/python2.7/unittest/loader.py&quot;, line 232, in _get_module_from_name
    __import__(name)
  File &quot;/home/travis/build/kaitai-io/ci_targets/tests/spec/python/test_expr_2.py&quot;, line 5, in &lt;module&gt;
    from expr_2 import Expr2
ImportError: No module named expr_2
" type="ImportError">
<![CDATA[ImportError: Failed to import test module: test_expr_2
Traceback (most recent call last):
  File "/opt/python/2.7.14/lib/python2.7/unittest/loader.py", line 254, in _find_tests
    module = self._get_module_from_name(name)
  File "/opt/python/2.7.14/lib/python2.7/unittest/loader.py", line 232, in _get_module_from_name
    __import__(name)
  File "/home/travis/build/kaitai-io/ci_targets/tests/spec/python/test_expr_2.py", line 5, in <module>
    from expr_2 import Expr2
ImportError: No module named expr_2

]]>		</error>
		<system-out>
<![CDATA[]]>		</system-out>
		<system-err>
<![CDATA[]]>		</system-err>
	</testcase>
	<testcase classname="unittest.loader.ModuleImportFailure" file="/opt/python/2.7.14/lib/python2.7/unittest/loader.py" line="31" name="test_expr_bytes_ops" time="0.000" timestamp="2021-02-06T14:35:09">
		<error message="Failed to import test module: test_expr_bytes_ops
Traceback (most recent call last):
  File &quot;/opt/python/2.7.14/lib/python2.7/unittest/loader.py&quot;, line 254, in _find_tests
    module = self._get_module_from_name(name)
  File &quot;/opt/python/2.7.14/lib/python2.7/unittest/loader.py&quot;, line 232, in _get_module_from_name
    __import__(name)
  File &quot;/home/travis/build/kaitai-io/ci_targets/tests/spec/python/test_expr_bytes_ops.py&quot;, line 5, in &lt;module&gt;
    from expr_bytes_ops import ExprBytesOps
ImportError: No module named expr_bytes_ops
" type="ImportError">
<![CDATA[ImportError: Failed to import test module: test_expr_bytes_ops
Traceback (most recent call last):
  File "/opt/python/2.7.14/lib/python2.7/unittest/loader.py", line 254, in _find_tests
    module = self._get_module_from_name(name)
  File "/opt/python/2.7.14/lib/python2.7/unittest/loader.py", line 232, in _get_module_from_name
    __import__(name)
  File "/home/travis/build/kaitai-io/ci_targets/tests/spec/python/test_expr_bytes_ops.py", line 5, in <module>
    from expr_bytes_ops import ExprBytesOps
ImportError: No module named expr_bytes_ops

]]>		</error>
		<system-out>
<![CDATA[]]>		</system-out>
		<system-err>
<![CDATA[]]>		</system-err>
	</testcase>
	<testcase classname="unittest.loader.ModuleImportFailure" file="/opt/python/2.7.14/lib/python2.7/unittest/loader.py" line="31" name="test_bcd_user_type_be" time="0.000" timestamp="2021-02-06T14:35:09">
		<error message="Failed to import test module: test_bcd_user_type_be
Traceback (most recent call last):
  File &quot;/opt/python/2.7.14/lib/python2.7/unittest/loader.py&quot;, line 254, in _find_tests
    module = self._get_module_from_name(name)
  File &quot;/opt/python/2.7.14/lib/python2.7/unittest/loader.py&quot;, line 232, in _get_module_from_name
    __import__(name)
  File &quot;/home/travis/build/kaitai-io/ci_targets/tests/spec/python/test_bcd_user_type_be.py&quot;, line 5, in &lt;module&gt;
    from bcd_user_type_be import BcdUserTypeBe
ImportError: No module named bcd_user_type_be
" type="ImportError">
<![CDATA[ImportError: Failed to import test module: test_bcd_user_type_be
Traceback (most recent call last):
  File "/opt/python/2.7.14/lib/python2.7/unittest/loader.py", line 254, in _find_tests
    module = self._get_module_from_name(name)
  File "/opt/python/2.7.14/lib/python2.7/unittest/loader.py", line 232, in _get_module_from_name
    __import__(name)
  File "/home/travis/build/kaitai-io/ci_targets/tests/spec/python/test_bcd_user_type_be.py", line 5, in <module>
    from bcd_user_type_be import BcdUserTypeBe
ImportError: No module named bcd_user_type_be

]]>		</error>
		<system-out>
<![CDATA[]]>		</system-out>
		<system-err>
<![CDATA[]]>		</system-err>
	</testcase>
	<testcase classname="unittest.loader.ModuleImportFailure" file="/opt/python/2.7.14/lib/python2.7/unittest/loader.py" line="31" name="test_float_to_i" time="0.000" timestamp="2021-02-06T14:35:09">
		<error message="Failed to import test module: test_float_to_i
Traceback (most recent call last):
  File &quot;/opt/python/2.7.14/lib/python2.7/unittest/loader.py&quot;, line 254, in _find_tests
    module = self._get_module_from_name(name)
  File &quot;/opt/python/2.7.14/lib/python2.7/unittest/loader.py&quot;, line 232, in _get_module_from_name
    __import__(name)
  File &quot;/home/travis/build/kaitai-io/ci_targets/tests/spec/python/test_float_to_i.py&quot;, line 5, in &lt;module&gt;
    from float_to_i import FloatToI
ImportError: No module named float_to_i
" type="ImportError">
<![CDATA[ImportError: Failed to import test module: test_float_to_i
Traceback (most recent call last):
  File "/opt/python/2.7.14/lib/python2.7/unittest/loader.py", line 254, in _find_tests
    module = self._get_module_from_name(name)
  File "/opt/python/2.7.14/lib/python2.7/unittest/loader.py", line 232, in _get_module_from_name
    __import__(name)
  File "/home/travis/build/kaitai-io/ci_targets/tests/spec/python/test_float_to_i.py", line 5, in <module>
    from float_to_i import FloatToI
ImportError: No module named float_to_i

]]>		</error>
		<system-out>
<![CDATA[]]>		</system-out>
		<system-err>
<![CDATA[]]>		</system-err>
	</testcase>
	<testcase classname="unittest.loader.ModuleImportFailure" file="/opt/python/2.7.14/lib/python2.7/unittest/loader.py" line="31" name="test_type_ternary_2nd_falsy" time="0.000" timestamp="2021-02-06T14:35:09">
		<error message="Failed to import test module: test_type_ternary_2nd_falsy
Traceback (most recent call last):
  File &quot;/opt/python/2.7.14/lib/python2.7/unittest/loader.py&quot;, line 254, in _find_tests
    module = self._get_module_from_name(name)
  File &quot;/opt/python/2.7.14/lib/python2.7/unittest/loader.py&quot;, line 232, in _get_module_from_name
    __import__(name)
  File &quot;/home/travis/build/kaitai-io/ci_targets/tests/spec/python/test_type_ternary_2nd_falsy.py&quot;, line 5, in &lt;module&gt;
    from type_ternary_2nd_falsy import TypeTernary2ndFalsy
ImportError: No module named type_ternary_2nd_falsy
" type="ImportError">
<![CDATA[ImportError: Failed to import test module: test_type_ternary_2nd_falsy
Traceback (most recent call last):
  File "/opt/python/2.7.14/lib/python2.7/unittest/loader.py", line 254, in _find_tests
    module = self._get_module_from_name(name)
  File "/opt/python/2.7.14/lib/python2.7/unittest/loader.py", line 232, in _get_module_from_name
    __import__(name)
  File "/home/travis/build/kaitai-io/ci_targets/tests/spec/python/test_type_ternary_2nd_falsy.py", line 5, in <module>
    from type_ternary_2nd_falsy import TypeTernary2ndFalsy
ImportError: No module named type_ternary_2nd_falsy

]]>		</error>
		<system-out>
<![CDATA[]]>		</system-out>
		<system-err>
<![CDATA[]]>		</system-err>
	</testcase>
	<testcase classname="unittest.loader.ModuleImportFailure" file="/opt/python/2.7.14/lib/python2.7/unittest/loader.py" line="31" name="test_combine_bytes" time="0.000" timestamp="2021-02-06T14:35:09">
		<error message="Failed to import test module: test_combine_bytes
Traceback (most recent call last):
  File &quot;/opt/python/2.7.14/lib/python2.7/unittest/loader.py&quot;, line 254, in _find_tests
    module = self._get_module_from_name(name)
  File &quot;/opt/python/2.7.14/lib/python2.7/unittest/loader.py&quot;, line 232, in _get_module_from_name
    __import__(name)
  File &quot;/home/travis/build/kaitai-io/ci_targets/tests/spec/python/test_combine_bytes.py&quot;, line 5, in &lt;module&gt;
    from combine_bytes import CombineBytes
ImportError: No module named combine_bytes
" type="ImportError">
<![CDATA[ImportError: Failed to import test module: test_combine_bytes
Traceback (most recent call last):
  File "/opt/python/2.7.14/lib/python2.7/unittest/loader.py", line 254, in _find_tests
    module = self._get_module_from_name(name)
  File "/opt/python/2.7.14/lib/python2.7/unittest/loader.py", line 232, in _get_module_from_name
    __import__(name)
  File "/home/travis/build/kaitai-io/ci_targets/tests/spec/python/test_combine_bytes.py", line 5, in <module>
    from combine_bytes import CombineBytes
ImportError: No module named combine_bytes

]]>		</error>
		<system-out>
<![CDATA[]]>		</system-out>
		<system-err>
<![CDATA[]]>		</system-err>
	</testcase>
	<testcase classname="unittest.loader.ModuleImportFailure" file="/opt/python/2.7.14/lib/python2.7/unittest/loader.py" line="31" name="test_enum_to_i_class_border_1" time="0.000" timestamp="2021-02-06T14:35:09">
		<error message="Failed to import test module: test_enum_to_i_class_border_1
Traceback (most recent call last):
  File &quot;/opt/python/2.7.14/lib/python2.7/unittest/loader.py&quot;, line 254, in _find_tests
    module = self._get_module_from_name(name)
  File &quot;/opt/python/2.7.14/lib/python2.7/unittest/loader.py&quot;, line 232, in _get_module_from_name
    __import__(name)
  File &quot;/home/travis/build/kaitai-io/ci_targets/tests/spec/python/test_enum_to_i_class_border_1.py&quot;, line 5, in &lt;module&gt;
    from enum_to_i_class_border_1 import EnumToIClassBorder1
ImportError: No module named enum_to_i_class_border_1
" type="ImportError">
<![CDATA[ImportError: Failed to import test module: test_enum_to_i_class_border_1
Traceback (most recent call last):
  File "/opt/python/2.7.14/lib/python2.7/unittest/loader.py", line 254, in _find_tests
    module = self._get_module_from_name(name)
  File "/opt/python/2.7.14/lib/python2.7/unittest/loader.py", line 232, in _get_module_from_name
    __import__(name)
  File "/home/travis/build/kaitai-io/ci_targets/tests/spec/python/test_enum_to_i_class_border_1.py", line 5, in <module>
    from enum_to_i_class_border_1 import EnumToIClassBorder1
ImportError: No module named enum_to_i_class_border_1

]]>		</error>
		<system-out>
<![CDATA[]]>		</system-out>
		<system-err>
<![CDATA[]]>		</system-err>
	</testcase>
	<testcase classname="unittest.loader.ModuleImportFailure" file="/opt/python/2.7.14/lib/python2.7/unittest/loader.py" line="31" name="test_expr_str_ops" time="0.000" timestamp="2021-02-06T14:35:09">
		<error message="Failed to import test module: test_expr_str_ops
Traceback (most recent call last):
  File &quot;/opt/python/2.7.14/lib/python2.7/unittest/loader.py&quot;, line 254, in _find_tests
    module = self._get_module_from_name(name)
  File &quot;/opt/python/2.7.14/lib/python2.7/unittest/loader.py&quot;, line 232, in _get_module_from_name
    __import__(name)
  File &quot;/home/travis/build/kaitai-io/ci_targets/tests/spec/python/test_expr_str_ops.py&quot;, line 5, in &lt;module&gt;
    from expr_str_ops import ExprStrOps
ImportError: No module named expr_str_ops
" type="ImportError">
<![CDATA[ImportError: Failed to import test module: test_expr_str_ops
Traceback (most recent call last):
  File "/opt/python/2.7.14/lib/python2.7/unittest/loader.py", line 254, in _find_tests
    module = self._get_module_from_name(name)
  File "/opt/python/2.7.14/lib/python2.7/unittest/loader.py", line 232, in _get_module_from_name
    __import__(name)
  File "/home/travis/build/kaitai-io/ci_targets/tests/spec/python/test_expr_str_ops.py", line 5, in <module>
    from expr_str_ops import ExprStrOps
ImportError: No module named expr_str_ops

]]>		</error>
		<system-out>
<![CDATA[]]>		</system-out>
		<system-err>
<![CDATA[]]>		</system-err>
	</testcase>
	<testcase classname="unittest.loader.ModuleImportFailure" file="/opt/python/2.7.14/lib/python2.7/unittest/loader.py" line="31" name="test_expr_calc_array_ops" time="0.000" timestamp="2021-02-06T14:35:09">
		<error message="Failed to import test module: test_expr_calc_array_ops
Traceback (most recent call last):
  File &quot;/opt/python/2.7.14/lib/python2.7/unittest/loader.py&quot;, line 254, in _find_tests
    module = self._get_module_from_name(name)
  File &quot;/opt/python/2.7.14/lib/python2.7/unittest/loader.py&quot;, line 232, in _get_module_from_name
    __import__(name)
  File &quot;/home/travis/build/kaitai-io/ci_targets/tests/spec/python/test_expr_calc_array_ops.py&quot;, line 5, in &lt;module&gt;
    from expr_calc_array_ops import ExprCalcArrayOps
ImportError: No module named expr_calc_array_ops
" type="ImportError">
<![CDATA[ImportError: Failed to import test module: test_expr_calc_array_ops
Traceback (most recent call last):
  File "/opt/python/2.7.14/lib/python2.7/unittest/loader.py", line 254, in _find_tests
    module = self._get_module_from_name(name)
  File "/opt/python/2.7.14/lib/python2.7/unittest/loader.py", line 232, in _get_module_from_name
    __import__(name)
  File "/home/travis/build/kaitai-io/ci_targets/tests/spec/python/test_expr_calc_array_ops.py", line 5, in <module>
    from expr_calc_array_ops import ExprCalcArrayOps
ImportError: No module named expr_calc_array_ops

]]>		</error>
		<system-out>
<![CDATA[]]>		</system-out>
		<system-err>
<![CDATA[]]>		</system-err>
	</testcase>
	<testcase classname="unittest.loader.ModuleImportFailure" file="/opt/python/2.7.14/lib/python2.7/unittest/loader.py" line="31" name="test_combine_str" time="0.000" timestamp="2021-02-06T14:35:09">
		<error message="Failed to import test module: test_combine_str
Traceback (most recent call last):
  File &quot;/opt/python/2.7.14/lib/python2.7/unittest/loader.py&quot;, line 254, in _find_tests
    module = self._get_module_from_name(name)
  File &quot;/opt/python/2.7.14/lib/python2.7/unittest/loader.py&quot;, line 232, in _get_module_from_name
    __import__(name)
  File &quot;/home/travis/build/kaitai-io/ci_targets/tests/spec/python/test_combine_str.py&quot;, line 5, in &lt;module&gt;
    from combine_str import CombineStr
ImportError: No module named combine_str
" type="ImportError">
<![CDATA[ImportError: Failed to import test module: test_combine_str
Traceback (most recent call last):
  File "/opt/python/2.7.14/lib/python2.7/unittest/loader.py", line 254, in _find_tests
    module = self._get_module_from_name(name)
  File "/opt/python/2.7.14/lib/python2.7/unittest/loader.py", line 232, in _get_module_from_name
    __import__(name)
  File "/home/travis/build/kaitai-io/ci_targets/tests/spec/python/test_combine_str.py", line 5, in <module>
    from combine_str import CombineStr
ImportError: No module named combine_str

]]>		</error>
		<system-out>
<![CDATA[]]>		</system-out>
		<system-err>
<![CDATA[]]>		</system-err>
	</testcase>
	<testcase classname="unittest.loader.ModuleImportFailure" file="/opt/python/2.7.14/lib/python2.7/unittest/loader.py" line="31" name="test_bcd_user_type_le" time="0.000" timestamp="2021-02-06T14:35:09">
		<error message="Failed to import test module: test_bcd_user_type_le
Traceback (most recent call last):
  File &quot;/opt/python/2.7.14/lib/python2.7/unittest/loader.py&quot;, line 254, in _find_tests
    module = self._get_module_from_name(name)
  File &quot;/opt/python/2.7.14/lib/python2.7/unittest/loader.py&quot;, line 232, in _get_module_from_name
    __import__(name)
  File &quot;/home/travis/build/kaitai-io/ci_targets/tests/spec/python/test_bcd_user_type_le.py&quot;, line 5, in &lt;module&gt;
    from bcd_user_type_le import BcdUserTypeLe
ImportError: No module named bcd_user_type_le
" type="ImportError">
<![CDATA[ImportError: Failed to import test module: test_bcd_user_type_le
Traceback (most recent call last):
  File "/opt/python/2.7.14/lib/python2.7/unittest/loader.py", line 254, in _find_tests
    module = self._get_module_from_name(name)
  File "/opt/python/2.7.14/lib/python2.7/unittest/loader.py", line 232, in _get_module_from_name
    __import__(name)
  File "/home/travis/build/kaitai-io/ci_targets/tests/spec/python/test_bcd_user_type_le.py", line 5, in <module>
    from bcd_user_type_le import BcdUserTypeLe
ImportError: No module named bcd_user_type_le

]]>		</error>
		<system-out>
<![CDATA[]]>		</system-out>
		<system-err>
<![CDATA[]]>		</system-err>
	</testcase>
	<testcase classname="unittest.loader.ModuleImportFailure" file="/opt/python/2.7.14/lib/python2.7/unittest/loader.py" line="31" name="test_expr_bytes_cmp" time="0.000" timestamp="2021-02-06T14:35:09">
		<error message="Failed to import test module: test_expr_bytes_cmp
Traceback (most recent call last):
  File &quot;/opt/python/2.7.14/lib/python2.7/unittest/loader.py&quot;, line 254, in _find_tests
    module = self._get_module_from_name(name)
  File &quot;/opt/python/2.7.14/lib/python2.7/unittest/loader.py&quot;, line 232, in _get_module_from_name
    __import__(name)
  File &quot;/home/travis/build/kaitai-io/ci_targets/tests/spec/python/test_expr_bytes_cmp.py&quot;, line 5, in &lt;module&gt;
    from expr_bytes_cmp import ExprBytesCmp
ImportError: No module named expr_bytes_cmp
" type="ImportError">
<![CDATA[ImportError: Failed to import test module: test_expr_bytes_cmp
Traceback (most recent call last):
  File "/opt/python/2.7.14/lib/python2.7/unittest/loader.py", line 254, in _find_tests
    module = self._get_module_from_name(name)
  File "/opt/python/2.7.14/lib/python2.7/unittest/loader.py", line 232, in _get_module_from_name
    __import__(name)
  File "/home/travis/build/kaitai-io/ci_targets/tests/spec/python/test_expr_bytes_cmp.py", line 5, in <module>
    from expr_bytes_cmp import ExprBytesCmp
ImportError: No module named expr_bytes_cmp

]]>		</error>
		<system-out>
<![CDATA[]]>		</system-out>
		<system-err>
<![CDATA[]]>		</system-err>
	</testcase>
	<testcase classname="unittest.loader.ModuleImportFailure" file="/opt/python/2.7.14/lib/python2.7/unittest/loader.py" line="31" name="test_expr_bytes_literal" time="0.000" timestamp="2021-02-06T14:35:09">
		<error message="Failed to import test module: test_expr_bytes_literal
Traceback (most recent call last):
  File &quot;/opt/python/2.7.14/lib/python2.7/unittest/loader.py&quot;, line 254, in _find_tests
    module = self._get_module_from_name(name)
  File &quot;/opt/python/2.7.14/lib/python2.7/unittest/loader.py&quot;, line 232, in _get_module_from_name
    __import__(name)
  File &quot;/home/travis/build/kaitai-io/ci_targets/tests/spec/python/test_expr_bytes_literal.py&quot;, line 5, in &lt;module&gt;
    from expr_bytes_literal import ExprBytesLiteral
ImportError: No module named expr_bytes_literal
" type="ImportError">
<![CDATA[ImportError: Failed to import test module: test_expr_bytes_literal
Traceback (most recent call last):
  File "/opt/python/2.7.14/lib/python2.7/unittest/loader.py", line 254, in _find_tests
    module = self._get_module_from_name(name)
  File "/opt/python/2.7.14/lib/python2.7/unittest/loader.py", line 232, in _get_module_from_name
    __import__(name)
  File "/home/travis/build/kaitai-io/ci_targets/tests/spec/python/test_expr_bytes_literal.py", line 5, in <module>
    from expr_bytes_literal import ExprBytesLiteral
ImportError: No module named expr_bytes_literal

]]>		</error>
		<system-out>
<![CDATA[]]>		</system-out>
		<system-err>
<![CDATA[]]>		</system-err>
	</testcase>
	<testcase classname="unittest.loader.ModuleImportFailure" file="/opt/python/2.7.14/lib/python2.7/unittest/loader.py" line="31" name="test_imports_abs" time="0.000" timestamp="2021-02-06T14:35:09">
		<error message="Failed to import test module: test_imports_abs
Traceback (most recent call last):
  File &quot;/opt/python/2.7.14/lib/python2.7/unittest/loader.py&quot;, line 254, in _find_tests
    module = self._get_module_from_name(name)
  File &quot;/opt/python/2.7.14/lib/python2.7/unittest/loader.py&quot;, line 232, in _get_module_from_name
    __import__(name)
  File &quot;/home/travis/build/kaitai-io/ci_targets/tests/spec/python/test_imports_abs.py&quot;, line 5, in &lt;module&gt;
    from imports_abs import ImportsAbs
ImportError: No module named imports_abs
" type="ImportError">
<![CDATA[ImportError: Failed to import test module: test_imports_abs
Traceback (most recent call last):
  File "/opt/python/2.7.14/lib/python2.7/unittest/loader.py", line 254, in _find_tests
    module = self._get_module_from_name(name)
  File "/opt/python/2.7.14/lib/python2.7/unittest/loader.py", line 232, in _get_module_from_name
    __import__(name)
  File "/home/travis/build/kaitai-io/ci_targets/tests/spec/python/test_imports_abs.py", line 5, in <module>
    from imports_abs import ImportsAbs
ImportError: No module named imports_abs

]]>		</error>
		<system-out>
<![CDATA[]]>		</system-out>
		<system-err>
<![CDATA[]]>		</system-err>
	</testcase>
	<testcase classname="unittest.loader.ModuleImportFailure" file="/opt/python/2.7.14/lib/python2.7/unittest/loader.py" line="31" name="test_expr_ops_parens" time="0.000" timestamp="2021-02-06T14:35:09">
		<error message="Failed to import test module: test_expr_ops_parens
Traceback (most recent call last):
  File &quot;/opt/python/2.7.14/lib/python2.7/unittest/loader.py&quot;, line 254, in _find_tests
    module = self._get_module_from_name(name)
  File &quot;/opt/python/2.7.14/lib/python2.7/unittest/loader.py&quot;, line 232, in _get_module_from_name
    __import__(name)
  File &quot;/home/travis/build/kaitai-io/ci_targets/tests/spec/python/test_expr_ops_parens.py&quot;, line 5, in &lt;module&gt;
    from expr_ops_parens import ExprOpsParens
ImportError: No module named expr_ops_parens
" type="ImportError">
<![CDATA[ImportError: Failed to import test module: test_expr_ops_parens
Traceback (most recent call last):
  File "/opt/python/2.7.14/lib/python2.7/unittest/loader.py", line 254, in _find_tests
    module = self._get_module_from_name(name)
  File "/opt/python/2.7.14/lib/python2.7/unittest/loader.py", line 232, in _get_module_from_name
    __import__(name)
  File "/home/travis/build/kaitai-io/ci_targets/tests/spec/python/test_expr_ops_parens.py", line 5, in <module>
    from expr_ops_parens import ExprOpsParens
ImportError: No module named expr_ops_parens

]]>		</error>
		<system-out>
<![CDATA[]]>		</system-out>
		<system-err>
<![CDATA[]]>		</system-err>
	</testcase>
</testsuite>
