<?xml version="1.0" encoding="UTF-8"?>
<testsuite errors="1" failures="0" name="test_instance_user_array.TestInstanceUserArray-20180127003042" skipped="0" tests="1" time="0.000">
	<testcase classname="test_instance_user_array.TestInstanceUserArray" name="test_instance_user_array" time="0.000">
		<error message="I/O operation on closed file" type="ValueError">
<![CDATA[Traceback (most recent call last):
  File "/home/travis/build/kaitai-io/ci_targets/tests/spec/python/test_instance_user_array.py", line 13, in test_instance_user_array
    self.assertEqual(r.user_entries[0].word1, 0x1111)
  File "/home/travis/build/kaitai-io/ci_targets/tests/compiled/python/instance_user_array.py", line 40, in user_entries
    _pos = self._io.pos()
  File "/home/travis/build/kaitai-io/ci_targets/runtime/python/kaitaistruct.py", line 76, in pos
    return self._io.tell()
ValueError: I/O operation on closed file
]]>		</error>
	</testcase>
	<system-out>
<![CDATA[]]>	</system-out>
	<system-err>
<![CDATA[]]>	</system-err>
</testsuite>
