<?xml version="1.0" encoding="UTF-8"?>
<testsuite errors="1" failures="0" name="test_multiple_use.TestMultipleUse-20180205014342" skipped="0" tests="1" time="0.001">
	<testcase classname="test_multiple_use.TestMultipleUse" name="test_multiple_use" time="0.001">
		<error message="I/O operation on closed file" type="ValueError">
<![CDATA[Traceback (most recent call last):
  File "/home/travis/build/kaitai-io/ci_targets/tests/spec/python/test_multiple_use.py", line 10, in test_multiple_use
    self.assertEqual(r.t2.second_use.value, 0x20)
  File "/home/travis/build/kaitai-io/ci_targets/tests/compiled/python/multiple_use.py", line 58, in second_use
    _pos = self._io.pos()
  File "/home/travis/build/kaitai-io/ci_targets/runtime/python/kaitaistruct.py", line 76, in pos
    return self._io.tell()
ValueError: I/O operation on closed file
]]>		</error>
	</testcase>
	<system-out>
<![CDATA[]]>	</system-out>
	<system-err>
<![CDATA[]]>	</system-err>
</testsuite>
